[2022-11-30T01:41:25.460+0000] {taskinstance.py:1165} INFO - Dependencies all met for <TaskInstance: dag_with_postgres_operator_v02.insert_into_table scheduled__2022-11-28T00:00:00+00:00 [queued]>
[2022-11-30T01:41:25.551+0000] {taskinstance.py:1165} INFO - Dependencies all met for <TaskInstance: dag_with_postgres_operator_v02.insert_into_table scheduled__2022-11-28T00:00:00+00:00 [queued]>
[2022-11-30T01:41:25.553+0000] {taskinstance.py:1362} INFO - 
--------------------------------------------------------------------------------
[2022-11-30T01:41:25.553+0000] {taskinstance.py:1363} INFO - Starting attempt 1 of 6
[2022-11-30T01:41:25.553+0000] {taskinstance.py:1364} INFO - 
--------------------------------------------------------------------------------
[2022-11-30T01:41:25.639+0000] {taskinstance.py:1383} INFO - Executing <Task(PostgresOperator): insert_into_table> on 2022-11-28 00:00:00+00:00
[2022-11-30T01:41:25.651+0000] {standard_task_runner.py:55} INFO - Started process 1332 to run task
[2022-11-30T01:41:25.668+0000] {standard_task_runner.py:82} INFO - Running: ['***', 'tasks', 'run', 'dag_with_postgres_operator_v02', 'insert_into_table', 'scheduled__2022-11-28T00:00:00+00:00', '--job-id', '150', '--raw', '--subdir', 'DAGS_FOLDER/dag_with_postgres_operator.py', '--cfg-path', '/tmp/tmpcia4bif0']
[2022-11-30T01:41:25.680+0000] {standard_task_runner.py:83} INFO - Job 150: Subtask insert_into_table
[2022-11-30T01:41:25.876+0000] {task_command.py:376} INFO - Running <TaskInstance: dag_with_postgres_operator_v02.insert_into_table scheduled__2022-11-28T00:00:00+00:00 [running]> on host 2c9b3e546def
[2022-11-30T01:41:25.975+0000] {abstractoperator.py:421} ERROR - Exception rendering Jinja template for task 'insert_into_table', field 'sql'. Template: "\n            insert into dag_runs (dt, dag_id) values ('{{ ds }}', '{{ dag.daug_id}}')\n        "
Traceback (most recent call last):
  File "/home/airflow/.local/lib/python3.7/site-packages/airflow/models/abstractoperator.py", line 414, in _do_render_template_fields
    seen_oids,
  File "/home/airflow/.local/lib/python3.7/site-packages/airflow/models/abstractoperator.py", line 474, in render_template
    return render_template_to_string(template, context)
  File "/home/airflow/.local/lib/python3.7/site-packages/airflow/utils/helpers.py", line 288, in render_template_to_string
    return render_template(template, cast(MutableMapping[str, Any], context), native=False)
  File "/home/airflow/.local/lib/python3.7/site-packages/airflow/utils/helpers.py", line 283, in render_template
    return "".join(nodes)
  File "<template>", line 16, in root
  File "/home/airflow/.local/lib/python3.7/site-packages/jinja2/runtime.py", line 852, in _fail_with_undefined_error
    raise self._undefined_exception(self._undefined_message)
jinja2.exceptions.UndefinedError: '***.models.dag.DAG object' has no attribute 'daug_id'
[2022-11-30T01:41:25.977+0000] {taskinstance.py:1851} ERROR - Task failed with exception
Traceback (most recent call last):
  File "/home/airflow/.local/lib/python3.7/site-packages/airflow/models/taskinstance.py", line 1457, in _run_raw_task
    self._execute_task_with_callbacks(context, test_mode)
  File "/home/airflow/.local/lib/python3.7/site-packages/airflow/models/taskinstance.py", line 1576, in _execute_task_with_callbacks
    task_orig = self.render_templates(context=context)
  File "/home/airflow/.local/lib/python3.7/site-packages/airflow/models/taskinstance.py", line 2199, in render_templates
    original_task.render_template_fields(context)
  File "/home/airflow/.local/lib/python3.7/site-packages/airflow/models/baseoperator.py", line 1193, in render_template_fields
    self._do_render_template_fields(self, self.template_fields, context, jinja_env, set())
  File "/home/airflow/.local/lib/python3.7/site-packages/airflow/utils/session.py", line 75, in wrapper
    return func(*args, session=session, **kwargs)
  File "/home/airflow/.local/lib/python3.7/site-packages/airflow/models/abstractoperator.py", line 414, in _do_render_template_fields
    seen_oids,
  File "/home/airflow/.local/lib/python3.7/site-packages/airflow/models/abstractoperator.py", line 474, in render_template
    return render_template_to_string(template, context)
  File "/home/airflow/.local/lib/python3.7/site-packages/airflow/utils/helpers.py", line 288, in render_template_to_string
    return render_template(template, cast(MutableMapping[str, Any], context), native=False)
  File "/home/airflow/.local/lib/python3.7/site-packages/airflow/utils/helpers.py", line 283, in render_template
    return "".join(nodes)
  File "<template>", line 16, in root
  File "/home/airflow/.local/lib/python3.7/site-packages/jinja2/runtime.py", line 852, in _fail_with_undefined_error
    raise self._undefined_exception(self._undefined_message)
jinja2.exceptions.UndefinedError: '***.models.dag.DAG object' has no attribute 'daug_id'
[2022-11-30T01:41:25.995+0000] {taskinstance.py:1406} INFO - Marking task as UP_FOR_RETRY. dag_id=dag_with_postgres_operator_v02, task_id=insert_into_table, execution_date=20221128T000000, start_date=20221130T014125, end_date=20221130T014125
[2022-11-30T01:41:26.016+0000] {standard_task_runner.py:105} ERROR - Failed to execute job 150 for task insert_into_table ('***.models.dag.DAG object' has no attribute 'daug_id'; 1332)
[2022-11-30T01:41:26.062+0000] {local_task_job.py:159} INFO - Task exited with return code 1
[2022-11-30T01:41:26.095+0000] {taskinstance.py:2623} INFO - 0 downstream tasks scheduled from follow-on schedule check
[2022-11-30T01:43:28.843+0000] {taskinstance.py:1165} INFO - Dependencies all met for <TaskInstance: dag_with_postgres_operator_v02.insert_into_table scheduled__2022-11-28T00:00:00+00:00 [queued]>
[2022-11-30T01:43:28.874+0000] {taskinstance.py:1165} INFO - Dependencies all met for <TaskInstance: dag_with_postgres_operator_v02.insert_into_table scheduled__2022-11-28T00:00:00+00:00 [queued]>
[2022-11-30T01:43:28.874+0000] {taskinstance.py:1362} INFO - 
--------------------------------------------------------------------------------
[2022-11-30T01:43:28.874+0000] {taskinstance.py:1363} INFO - Starting attempt 1 of 6
[2022-11-30T01:43:28.874+0000] {taskinstance.py:1364} INFO - 
--------------------------------------------------------------------------------
[2022-11-30T01:43:28.892+0000] {taskinstance.py:1383} INFO - Executing <Task(PostgresOperator): insert_into_table> on 2022-11-28 00:00:00+00:00
[2022-11-30T01:43:28.913+0000] {standard_task_runner.py:55} INFO - Started process 1579 to run task
[2022-11-30T01:43:28.922+0000] {standard_task_runner.py:82} INFO - Running: ['***', 'tasks', 'run', 'dag_with_postgres_operator_v02', 'insert_into_table', 'scheduled__2022-11-28T00:00:00+00:00', '--job-id', '161', '--raw', '--subdir', 'DAGS_FOLDER/dag_with_postgres_operator.py', '--cfg-path', '/tmp/tmp2pb7yo1p']
[2022-11-30T01:43:28.923+0000] {standard_task_runner.py:83} INFO - Job 161: Subtask insert_into_table
[2022-11-30T01:43:29.067+0000] {task_command.py:376} INFO - Running <TaskInstance: dag_with_postgres_operator_v02.insert_into_table scheduled__2022-11-28T00:00:00+00:00 [running]> on host 2c9b3e546def
[2022-11-30T01:43:29.193+0000] {taskinstance.py:1592} INFO - Exporting the following env vars:
AIRFLOW_CTX_DAG_OWNER=Bruno Lima
AIRFLOW_CTX_DAG_ID=dag_with_postgres_operator_v02
AIRFLOW_CTX_TASK_ID=insert_into_table
AIRFLOW_CTX_EXECUTION_DATE=2022-11-28T00:00:00+00:00
AIRFLOW_CTX_TRY_NUMBER=1
AIRFLOW_CTX_DAG_RUN_ID=scheduled__2022-11-28T00:00:00+00:00
[2022-11-30T01:43:29.203+0000] {base.py:71} INFO - Using connection ID 'postgres_localhost' for task execution.
[2022-11-30T01:43:29.211+0000] {sql.py:315} INFO - Running statement: 
            insert into dag_runs (dt,   ) values ('2022-11-28', 'dag_with_postgres_operator_v02')
        , parameters: None
[2022-11-30T01:43:29.212+0000] {taskinstance.py:1851} ERROR - Task failed with exception
Traceback (most recent call last):
  File "/home/airflow/.local/lib/python3.7/site-packages/airflow/providers/postgres/operators/postgres.py", line 94, in execute
    self.hook.run(self.sql, self.autocommit, parameters=self.parameters)
  File "/home/airflow/.local/lib/python3.7/site-packages/airflow/providers/common/sql/hooks/sql.py", line 295, in run
    self._run_command(cur, sql_statement, parameters)
  File "/home/airflow/.local/lib/python3.7/site-packages/airflow/providers/common/sql/hooks/sql.py", line 320, in _run_command
    cur.execute(sql_statement)
psycopg2.errors.SyntaxError: syntax error at or near ")"
LINE 2:             insert into dag_runs (dt,   ) values ('2022-11-2...
                                                ^

[2022-11-30T01:43:29.229+0000] {taskinstance.py:1406} INFO - Marking task as UP_FOR_RETRY. dag_id=dag_with_postgres_operator_v02, task_id=insert_into_table, execution_date=20221128T000000, start_date=20221130T014328, end_date=20221130T014329
[2022-11-30T01:43:29.267+0000] {standard_task_runner.py:105} ERROR - Failed to execute job 161 for task insert_into_table (syntax error at or near ")"
LINE 2:             insert into dag_runs (dt,   ) values ('2022-11-2...
                                                ^
; 1579)
[2022-11-30T01:43:29.290+0000] {local_task_job.py:159} INFO - Task exited with return code 1
[2022-11-30T01:43:29.315+0000] {taskinstance.py:2623} INFO - 0 downstream tasks scheduled from follow-on schedule check
[2022-11-30T01:44:26.690+0000] {taskinstance.py:1165} INFO - Dependencies all met for <TaskInstance: dag_with_postgres_operator_v02.insert_into_table scheduled__2022-11-28T00:00:00+00:00 [queued]>
[2022-11-30T01:44:26.707+0000] {taskinstance.py:1165} INFO - Dependencies all met for <TaskInstance: dag_with_postgres_operator_v02.insert_into_table scheduled__2022-11-28T00:00:00+00:00 [queued]>
[2022-11-30T01:44:26.708+0000] {taskinstance.py:1362} INFO - 
--------------------------------------------------------------------------------
[2022-11-30T01:44:26.708+0000] {taskinstance.py:1363} INFO - Starting attempt 1 of 6
[2022-11-30T01:44:26.708+0000] {taskinstance.py:1364} INFO - 
--------------------------------------------------------------------------------
[2022-11-30T01:44:26.759+0000] {taskinstance.py:1383} INFO - Executing <Task(PostgresOperator): insert_into_table> on 2022-11-28 00:00:00+00:00
[2022-11-30T01:44:26.766+0000] {standard_task_runner.py:55} INFO - Started process 1704 to run task
[2022-11-30T01:44:26.770+0000] {standard_task_runner.py:82} INFO - Running: ['***', 'tasks', 'run', 'dag_with_postgres_operator_v02', 'insert_into_table', 'scheduled__2022-11-28T00:00:00+00:00', '--job-id', '171', '--raw', '--subdir', 'DAGS_FOLDER/dag_with_postgres_operator.py', '--cfg-path', '/tmp/tmph3rb6hy2']
[2022-11-30T01:44:26.772+0000] {standard_task_runner.py:83} INFO - Job 171: Subtask insert_into_table
[2022-11-30T01:44:26.878+0000] {task_command.py:376} INFO - Running <TaskInstance: dag_with_postgres_operator_v02.insert_into_table scheduled__2022-11-28T00:00:00+00:00 [running]> on host 2c9b3e546def
[2022-11-30T01:44:26.971+0000] {taskinstance.py:1592} INFO - Exporting the following env vars:
AIRFLOW_CTX_DAG_OWNER=Bruno Lima
AIRFLOW_CTX_DAG_ID=dag_with_postgres_operator_v02
AIRFLOW_CTX_TASK_ID=insert_into_table
AIRFLOW_CTX_EXECUTION_DATE=2022-11-28T00:00:00+00:00
AIRFLOW_CTX_TRY_NUMBER=1
AIRFLOW_CTX_DAG_RUN_ID=scheduled__2022-11-28T00:00:00+00:00
[2022-11-30T01:44:26.987+0000] {base.py:71} INFO - Using connection ID 'postgres_localhost' for task execution.
[2022-11-30T01:44:26.991+0000] {sql.py:315} INFO - Running statement: 
            insert into dag_runs (dt, dag_id) values ('2022-11-28', 'dag_with_postgres_operator_v02')
        , parameters: None
[2022-11-30T01:44:26.992+0000] {sql.py:324} INFO - Rows affected: 1
[2022-11-30T01:44:27.014+0000] {taskinstance.py:1406} INFO - Marking task as SUCCESS. dag_id=dag_with_postgres_operator_v02, task_id=insert_into_table, execution_date=20221128T000000, start_date=20221130T014426, end_date=20221130T014427
[2022-11-30T01:44:27.067+0000] {local_task_job.py:159} INFO - Task exited with return code 0
[2022-11-30T01:44:27.091+0000] {taskinstance.py:2623} INFO - 0 downstream tasks scheduled from follow-on schedule check
