[2022-11-30T01:41:25.172+0000] {taskinstance.py:1165} INFO - Dependencies all met for <TaskInstance: dag_with_postgres_operator_v02.insert_into_table scheduled__2022-11-29T00:00:00+00:00 [queued]>
[2022-11-30T01:41:25.184+0000] {taskinstance.py:1165} INFO - Dependencies all met for <TaskInstance: dag_with_postgres_operator_v02.insert_into_table scheduled__2022-11-29T00:00:00+00:00 [queued]>
[2022-11-30T01:41:25.184+0000] {taskinstance.py:1362} INFO - 
--------------------------------------------------------------------------------
[2022-11-30T01:41:25.184+0000] {taskinstance.py:1363} INFO - Starting attempt 1 of 6
[2022-11-30T01:41:25.185+0000] {taskinstance.py:1364} INFO - 
--------------------------------------------------------------------------------
[2022-11-30T01:41:25.219+0000] {taskinstance.py:1383} INFO - Executing <Task(PostgresOperator): insert_into_table> on 2022-11-29 00:00:00+00:00
[2022-11-30T01:41:25.224+0000] {standard_task_runner.py:55} INFO - Started process 1330 to run task
[2022-11-30T01:41:25.239+0000] {standard_task_runner.py:82} INFO - Running: ['***', 'tasks', 'run', 'dag_with_postgres_operator_v02', 'insert_into_table', 'scheduled__2022-11-29T00:00:00+00:00', '--job-id', '149', '--raw', '--subdir', 'DAGS_FOLDER/dag_with_postgres_operator.py', '--cfg-path', '/tmp/tmp6knvoxbz']
[2022-11-30T01:41:25.243+0000] {standard_task_runner.py:83} INFO - Job 149: Subtask insert_into_table
[2022-11-30T01:41:25.498+0000] {task_command.py:376} INFO - Running <TaskInstance: dag_with_postgres_operator_v02.insert_into_table scheduled__2022-11-29T00:00:00+00:00 [running]> on host 2c9b3e546def
[2022-11-30T01:41:25.677+0000] {abstractoperator.py:421} ERROR - Exception rendering Jinja template for task 'insert_into_table', field 'sql'. Template: "\n            insert into dag_runs (dt, dag_id) values ('{{ ds }}', '{{ dag.daug_id}}')\n        "
Traceback (most recent call last):
  File "/home/airflow/.local/lib/python3.7/site-packages/airflow/models/abstractoperator.py", line 414, in _do_render_template_fields
    seen_oids,
  File "/home/airflow/.local/lib/python3.7/site-packages/airflow/models/abstractoperator.py", line 474, in render_template
    return render_template_to_string(template, context)
  File "/home/airflow/.local/lib/python3.7/site-packages/airflow/utils/helpers.py", line 288, in render_template_to_string
    return render_template(template, cast(MutableMapping[str, Any], context), native=False)
  File "/home/airflow/.local/lib/python3.7/site-packages/airflow/utils/helpers.py", line 283, in render_template
    return "".join(nodes)
  File "<template>", line 16, in root
  File "/home/airflow/.local/lib/python3.7/site-packages/jinja2/runtime.py", line 852, in _fail_with_undefined_error
    raise self._undefined_exception(self._undefined_message)
jinja2.exceptions.UndefinedError: '***.models.dag.DAG object' has no attribute 'daug_id'
[2022-11-30T01:41:25.681+0000] {taskinstance.py:1851} ERROR - Task failed with exception
Traceback (most recent call last):
  File "/home/airflow/.local/lib/python3.7/site-packages/airflow/models/taskinstance.py", line 1457, in _run_raw_task
    self._execute_task_with_callbacks(context, test_mode)
  File "/home/airflow/.local/lib/python3.7/site-packages/airflow/models/taskinstance.py", line 1576, in _execute_task_with_callbacks
    task_orig = self.render_templates(context=context)
  File "/home/airflow/.local/lib/python3.7/site-packages/airflow/models/taskinstance.py", line 2199, in render_templates
    original_task.render_template_fields(context)
  File "/home/airflow/.local/lib/python3.7/site-packages/airflow/models/baseoperator.py", line 1193, in render_template_fields
    self._do_render_template_fields(self, self.template_fields, context, jinja_env, set())
  File "/home/airflow/.local/lib/python3.7/site-packages/airflow/utils/session.py", line 75, in wrapper
    return func(*args, session=session, **kwargs)
  File "/home/airflow/.local/lib/python3.7/site-packages/airflow/models/abstractoperator.py", line 414, in _do_render_template_fields
    seen_oids,
  File "/home/airflow/.local/lib/python3.7/site-packages/airflow/models/abstractoperator.py", line 474, in render_template
    return render_template_to_string(template, context)
  File "/home/airflow/.local/lib/python3.7/site-packages/airflow/utils/helpers.py", line 288, in render_template_to_string
    return render_template(template, cast(MutableMapping[str, Any], context), native=False)
  File "/home/airflow/.local/lib/python3.7/site-packages/airflow/utils/helpers.py", line 283, in render_template
    return "".join(nodes)
  File "<template>", line 16, in root
  File "/home/airflow/.local/lib/python3.7/site-packages/jinja2/runtime.py", line 852, in _fail_with_undefined_error
    raise self._undefined_exception(self._undefined_message)
jinja2.exceptions.UndefinedError: '***.models.dag.DAG object' has no attribute 'daug_id'
[2022-11-30T01:41:25.737+0000] {taskinstance.py:1406} INFO - Marking task as UP_FOR_RETRY. dag_id=dag_with_postgres_operator_v02, task_id=insert_into_table, execution_date=20221129T000000, start_date=20221130T014125, end_date=20221130T014125
[2022-11-30T01:41:25.807+0000] {standard_task_runner.py:105} ERROR - Failed to execute job 149 for task insert_into_table ('***.models.dag.DAG object' has no attribute 'daug_id'; 1330)
[2022-11-30T01:41:25.880+0000] {local_task_job.py:159} INFO - Task exited with return code 1
[2022-11-30T01:41:26.057+0000] {taskinstance.py:2623} INFO - 0 downstream tasks scheduled from follow-on schedule check
[2022-11-30T01:43:29.081+0000] {taskinstance.py:1165} INFO - Dependencies all met for <TaskInstance: dag_with_postgres_operator_v02.insert_into_table scheduled__2022-11-29T00:00:00+00:00 [queued]>
[2022-11-30T01:43:29.097+0000] {taskinstance.py:1165} INFO - Dependencies all met for <TaskInstance: dag_with_postgres_operator_v02.insert_into_table scheduled__2022-11-29T00:00:00+00:00 [queued]>
[2022-11-30T01:43:29.097+0000] {taskinstance.py:1362} INFO - 
--------------------------------------------------------------------------------
[2022-11-30T01:43:29.098+0000] {taskinstance.py:1363} INFO - Starting attempt 1 of 6
[2022-11-30T01:43:29.098+0000] {taskinstance.py:1364} INFO - 
--------------------------------------------------------------------------------
[2022-11-30T01:43:29.117+0000] {taskinstance.py:1383} INFO - Executing <Task(PostgresOperator): insert_into_table> on 2022-11-29 00:00:00+00:00
[2022-11-30T01:43:29.129+0000] {standard_task_runner.py:55} INFO - Started process 1582 to run task
[2022-11-30T01:43:29.136+0000] {standard_task_runner.py:82} INFO - Running: ['***', 'tasks', 'run', 'dag_with_postgres_operator_v02', 'insert_into_table', 'scheduled__2022-11-29T00:00:00+00:00', '--job-id', '164', '--raw', '--subdir', 'DAGS_FOLDER/dag_with_postgres_operator.py', '--cfg-path', '/tmp/tmp31acg1n_']
[2022-11-30T01:43:29.138+0000] {standard_task_runner.py:83} INFO - Job 164: Subtask insert_into_table
[2022-11-30T01:43:29.226+0000] {task_command.py:376} INFO - Running <TaskInstance: dag_with_postgres_operator_v02.insert_into_table scheduled__2022-11-29T00:00:00+00:00 [running]> on host 2c9b3e546def
[2022-11-30T01:43:29.371+0000] {taskinstance.py:1592} INFO - Exporting the following env vars:
AIRFLOW_CTX_DAG_OWNER=Bruno Lima
AIRFLOW_CTX_DAG_ID=dag_with_postgres_operator_v02
AIRFLOW_CTX_TASK_ID=insert_into_table
AIRFLOW_CTX_EXECUTION_DATE=2022-11-29T00:00:00+00:00
AIRFLOW_CTX_TRY_NUMBER=1
AIRFLOW_CTX_DAG_RUN_ID=scheduled__2022-11-29T00:00:00+00:00
[2022-11-30T01:43:29.385+0000] {base.py:71} INFO - Using connection ID 'postgres_localhost' for task execution.
[2022-11-30T01:43:29.407+0000] {sql.py:315} INFO - Running statement: 
            insert into dag_runs (dt,   ) values ('2022-11-29', 'dag_with_postgres_operator_v02')
        , parameters: None
[2022-11-30T01:43:29.408+0000] {taskinstance.py:1851} ERROR - Task failed with exception
Traceback (most recent call last):
  File "/home/airflow/.local/lib/python3.7/site-packages/airflow/providers/postgres/operators/postgres.py", line 94, in execute
    self.hook.run(self.sql, self.autocommit, parameters=self.parameters)
  File "/home/airflow/.local/lib/python3.7/site-packages/airflow/providers/common/sql/hooks/sql.py", line 295, in run
    self._run_command(cur, sql_statement, parameters)
  File "/home/airflow/.local/lib/python3.7/site-packages/airflow/providers/common/sql/hooks/sql.py", line 320, in _run_command
    cur.execute(sql_statement)
psycopg2.errors.SyntaxError: syntax error at or near ")"
LINE 2:             insert into dag_runs (dt,   ) values ('2022-11-2...
                                                ^

[2022-11-30T01:43:29.421+0000] {taskinstance.py:1406} INFO - Marking task as UP_FOR_RETRY. dag_id=dag_with_postgres_operator_v02, task_id=insert_into_table, execution_date=20221129T000000, start_date=20221130T014329, end_date=20221130T014329
[2022-11-30T01:43:29.434+0000] {standard_task_runner.py:105} ERROR - Failed to execute job 164 for task insert_into_table (syntax error at or near ")"
LINE 2:             insert into dag_runs (dt,   ) values ('2022-11-2...
                                                ^
; 1582)
[2022-11-30T01:43:29.471+0000] {local_task_job.py:159} INFO - Task exited with return code 1
[2022-11-30T01:43:29.493+0000] {taskinstance.py:2623} INFO - 0 downstream tasks scheduled from follow-on schedule check
[2022-11-30T01:44:26.890+0000] {taskinstance.py:1165} INFO - Dependencies all met for <TaskInstance: dag_with_postgres_operator_v02.insert_into_table scheduled__2022-11-29T00:00:00+00:00 [queued]>
[2022-11-30T01:44:26.908+0000] {taskinstance.py:1165} INFO - Dependencies all met for <TaskInstance: dag_with_postgres_operator_v02.insert_into_table scheduled__2022-11-29T00:00:00+00:00 [queued]>
[2022-11-30T01:44:26.908+0000] {taskinstance.py:1362} INFO - 
--------------------------------------------------------------------------------
[2022-11-30T01:44:26.908+0000] {taskinstance.py:1363} INFO - Starting attempt 1 of 6
[2022-11-30T01:44:26.908+0000] {taskinstance.py:1364} INFO - 
--------------------------------------------------------------------------------
[2022-11-30T01:44:26.939+0000] {taskinstance.py:1383} INFO - Executing <Task(PostgresOperator): insert_into_table> on 2022-11-29 00:00:00+00:00
[2022-11-30T01:44:26.945+0000] {standard_task_runner.py:55} INFO - Started process 1707 to run task
[2022-11-30T01:44:26.957+0000] {standard_task_runner.py:82} INFO - Running: ['***', 'tasks', 'run', 'dag_with_postgres_operator_v02', 'insert_into_table', 'scheduled__2022-11-29T00:00:00+00:00', '--job-id', '174', '--raw', '--subdir', 'DAGS_FOLDER/dag_with_postgres_operator.py', '--cfg-path', '/tmp/tmpprv4jgde']
[2022-11-30T01:44:26.959+0000] {standard_task_runner.py:83} INFO - Job 174: Subtask insert_into_table
[2022-11-30T01:44:27.048+0000] {task_command.py:376} INFO - Running <TaskInstance: dag_with_postgres_operator_v02.insert_into_table scheduled__2022-11-29T00:00:00+00:00 [running]> on host 2c9b3e546def
[2022-11-30T01:44:27.171+0000] {taskinstance.py:1592} INFO - Exporting the following env vars:
AIRFLOW_CTX_DAG_OWNER=Bruno Lima
AIRFLOW_CTX_DAG_ID=dag_with_postgres_operator_v02
AIRFLOW_CTX_TASK_ID=insert_into_table
AIRFLOW_CTX_EXECUTION_DATE=2022-11-29T00:00:00+00:00
AIRFLOW_CTX_TRY_NUMBER=1
AIRFLOW_CTX_DAG_RUN_ID=scheduled__2022-11-29T00:00:00+00:00
[2022-11-30T01:44:27.183+0000] {base.py:71} INFO - Using connection ID 'postgres_localhost' for task execution.
[2022-11-30T01:44:27.186+0000] {sql.py:315} INFO - Running statement: 
            insert into dag_runs (dt, dag_id) values ('2022-11-29', 'dag_with_postgres_operator_v02')
        , parameters: None
[2022-11-30T01:44:27.187+0000] {sql.py:324} INFO - Rows affected: 1
[2022-11-30T01:44:27.199+0000] {taskinstance.py:1406} INFO - Marking task as SUCCESS. dag_id=dag_with_postgres_operator_v02, task_id=insert_into_table, execution_date=20221129T000000, start_date=20221130T014426, end_date=20221130T014427
[2022-11-30T01:44:27.256+0000] {local_task_job.py:159} INFO - Task exited with return code 0
[2022-11-30T01:44:27.286+0000] {taskinstance.py:2623} INFO - 0 downstream tasks scheduled from follow-on schedule check
