[2022-11-26T20:27:01.695+0000] {taskinstance.py:1165} INFO - Dependencies all met for <TaskInstance: our_dag_with_python_operator_v04.greet scheduled__2022-11-25T00:00:00+00:00 [queued]>
[2022-11-26T20:27:01.707+0000] {taskinstance.py:1165} INFO - Dependencies all met for <TaskInstance: our_dag_with_python_operator_v04.greet scheduled__2022-11-25T00:00:00+00:00 [queued]>
[2022-11-26T20:27:01.707+0000] {taskinstance.py:1362} INFO - 
--------------------------------------------------------------------------------
[2022-11-26T20:27:01.707+0000] {taskinstance.py:1363} INFO - Starting attempt 2 of 6
[2022-11-26T20:27:01.707+0000] {taskinstance.py:1364} INFO - 
--------------------------------------------------------------------------------
[2022-11-26T20:27:01.726+0000] {taskinstance.py:1383} INFO - Executing <Task(PythonOperator): greet> on 2022-11-25 00:00:00+00:00
[2022-11-26T20:27:01.730+0000] {standard_task_runner.py:55} INFO - Started process 2560 to run task
[2022-11-26T20:27:01.732+0000] {standard_task_runner.py:82} INFO - Running: ['***', 'tasks', 'run', 'our_dag_with_python_operator_v04', 'greet', 'scheduled__2022-11-25T00:00:00+00:00', '--job-id', '12', '--raw', '--subdir', 'DAGS_FOLDER/create_dag_with_python_operator.py', '--cfg-path', '/tmp/tmp2wyqf_hh']
[2022-11-26T20:27:01.734+0000] {standard_task_runner.py:83} INFO - Job 12: Subtask greet
[2022-11-26T20:27:01.841+0000] {task_command.py:376} INFO - Running <TaskInstance: our_dag_with_python_operator_v04.greet scheduled__2022-11-25T00:00:00+00:00 [running]> on host 3d834fabdefd
[2022-11-26T20:27:01.943+0000] {taskinstance.py:1592} INFO - Exporting the following env vars:
AIRFLOW_CTX_DAG_OWNER=burno
AIRFLOW_CTX_DAG_ID=our_dag_with_python_operator_v04
AIRFLOW_CTX_TASK_ID=greet
AIRFLOW_CTX_EXECUTION_DATE=2022-11-25T00:00:00+00:00
AIRFLOW_CTX_TRY_NUMBER=2
AIRFLOW_CTX_DAG_RUN_ID=scheduled__2022-11-25T00:00:00+00:00
[2022-11-26T20:27:01.966+0000] {taskinstance.py:1851} ERROR - Task failed with exception
Traceback (most recent call last):
  File "/home/airflow/.local/lib/python3.7/site-packages/airflow/operators/python.py", line 175, in execute
    return_value = self.execute_callable()
  File "/home/airflow/.local/lib/python3.7/site-packages/airflow/operators/python.py", line 193, in execute_callable
    return self.python_callable(*self.op_args, **self.op_kwargs)
  File "/opt/airflow/dags/create_dag_with_python_operator.py", line 16, in greet
    print(f"Hello World! My name is {name}, and I am {age} years old!")
NameError: name 'name' is not defined
[2022-11-26T20:27:01.979+0000] {taskinstance.py:1406} INFO - Marking task as UP_FOR_RETRY. dag_id=our_dag_with_python_operator_v04, task_id=greet, execution_date=20221125T000000, start_date=20221126T202701, end_date=20221126T202701
[2022-11-26T20:27:01.994+0000] {standard_task_runner.py:105} ERROR - Failed to execute job 12 for task greet (name 'name' is not defined; 2560)
[2022-11-26T20:27:02.025+0000] {local_task_job.py:159} INFO - Task exited with return code 1
[2022-11-26T20:27:02.044+0000] {taskinstance.py:2623} INFO - 0 downstream tasks scheduled from follow-on schedule check
